Workbook

Sheet Raw_Post_Data
A1: Post ID | B1: Platform | C1: Date | D1: Content Type | E1: Post Text | F1: Likes | G1: Shares | H1: Comments | I1: Impressions | J1: Reach | K1: Clicks | L1: Hashtags Used | M1: Campaign_Name
A2: P001 | B2: Twitter | C2: 2024-12-23 | D2: Reel | E2: Explore the latest reel on Myntra! Trendy styles await. | F2: 1461 | G2: 184 | H2: 344 | I2: 21915 | J2: 21675 | K2: 15 | L2: #MyntraSale | M2: FashionUpgrade
A3: P002 | B3: Twitter | C3: 2025-04-03 | D3: Text | E3: Explore the latest text on Myntra! Trendy styles await. | F3: 4054 | G3: 389 | H3: 493 | I3: 64864 | J3: 64383 | K3: 117 | L3: #MyntraFashion | M3: EndOfSeasonSale
A4: P003 | B4: YouTube | C4: 2025-05-12 | D4: Reel | E4: Explore the latest reel on Myntra! Trendy styles await. | F4: 2795 | G4: 105 | H4: 49 | I4: 53105 | J4: 52307 | K4: 204 | L4: #MyntraFashion,#MyntraSale | M4: FashionUpgrade
A5: P004 | B5: Instagram | C5: 2024-08-12 | D5: Story | E5: Explore the latest story on Myntra! Trendy styles await. | F5: 2404 | G5: 363 | H5: 138 | I5: 19232 | J5: 18636 | K5: 128 | L5: #MyntraSale | M5: FashionUpgrade | P5: video link
A6: P005 | B6: YouTube | C6: 2024-06-26 | D6: Reel | E6: Explore the latest reel on Myntra! Trendy styles await. | F6: 3557 | G6: 687 | H6: 424 | I6: 71140 | J6: 70701 | K6: 224 | L6: #StyleWithMyntra,#MyntraFashion | M6: MyntraFestiveEdit
A7: P006 | B7: Facebook | C7: 2024-10-31 | D7: Carousel | E7: Explore the latest carousel on Myntra! Trendy styles await. | F7: 2945 | G7: 930 | H7: 355 | I7: 23560 | J7: 23275 | K7: 256 | L7: #MyntraTrend | M7: EndOfSeasonSale
A8: P007 | B8: Twitter | C8: 2024-06-24 | D8: Carousel | E8: Explore the latest carousel on Myntra! Trendy styles await. | F8: 3860 | G8: 201 | H8: 279 | I8: 61760 | J8: 61660 | K8: 235 | L8: #MyntraTrend | M8: MyntraFestiveEdit
A9: P008 | B9: YouTube | C9: 2024-07-13 | D9: Image | E9: Explore the latest image on Myntra! Trendy styles await. | F9: 3929 | G9: 262 | H9: 278 | I9: 43219 | J9: 42841 | K9: 39 | L9: #MyntraFashion,#MyntraSale | M9: MyntraFestiveEdit
A10: P009 | B10: Facebook | C10: 2024-08-30 | D10: Text | E10: Explore the latest text on Myntra! Trendy styles await. | F10: 3784 | G10: 808 | H10: 404 | I10: 56760 | J10: 56343 | K10: 131 | L10: #MyntraFashion,#MyntraSale | M10: MyntraFestiveEdit
A11: P010 | B11: Facebook | C11: 2025-03-11 | D11: Image | E11: Explore the latest image on Myntra! Trendy styles await. | F11: 4241 | G11: 902 | H11: 47 | I11: 72097 | J11: 71598 | K11: 167 | L11: #MyntraTrend | M11: StyleRevolution
A12: P011 | B12: Instagram | C12: 2025-02-02 | D12: Story | E12: Explore the latest story on Myntra! Trendy styles await. | F12: 1792 | G12: 614 | H12: 497 | I12: 25088 | J12: 24675 | K12: 65 | L12: #StyleWithMyntra | M12: FashionUpgrade
A13: P012 | B13: Facebook | C13: 2024-07-21 | D13: Reel | E13: Explore the latest reel on Myntra! Trendy styles await. | F13: 1946 | G13: 686 | H13: 377 | I13: 23352 | J13: 22982 | K13: 213 | L13: #StyleWithMyntra,#MyntraSale | M13: MyntraFestiveEdit
A14: P013 | B14: YouTube | C14: 2024-11-18 | D14: Carousel | E14: Explore the latest carousel on Myntra! Trendy styles await. | F14: 1171 | G14: 286 | H14: 231 | I14: 22249 | J14: 21282 | K14: 114 | L14: #MyntraFashion | M14: StyleRevolution
A15: P014 | B15: Facebook | C15: 2025-02-16 | D15: Story | E15: Explore the latest story on Myntra! Trendy styles await. | F15: 4242 | G15: 555 | H15: 131 | I15: 33936 | J15: 33802 | K15: 265 | L15: #MyntraSale,#MyntraFashion | M15: MyntraFestiveEdit
A16: P015 | B16: Facebook | C16: 2024-10-24 | D16: Video | E16: Explore the latest video on Myntra! Trendy styles await. | F16: 3888 | G16: 604 | H16: 128 | I16: 77760 | J16: 77167 | K16: 20 | L16: #MyntraFashion,#FashionDeals | M16: FashionUpgrade
A17: P016 | B17: Facebook | C17: 2024-08-26 | D17: Text | E17: Explore the latest text on Myntra! Trendy styles await. | F17: 3452 | G17: 377 | H17: 360 | I17: 55232 | J17: 55075 | K17: 87 | L17: #MyntraSale,#FashionDeals | M17: MyntraFestiveEdit
... A301: P300 | B301: Twitter | C301: 2024-08-31 | D301: Carousel | E301: Explore the latest carousel on Myntra! Trendy styles await. | F301: 4494 | G301: 717 | H301: 45 | I301: 62916 | J301: 62688 | K301: 191 | L301: #MyntraFashion | M301: FashionUpgrade

Sheet Sheet1

Sheet Engagment Summary 
A1: Week_Start_Date | B1: Platform | C1: New_Followers | D1: Unfollows | E1: Total_Followers | F1: Engagement_Rate | G1: Ad_Spend | H1: Follower_Growth
A2: 45446 | B2: Instagram | C2: 1135 | D2: 88 | E2: 344084 | F2: 8.06 | G2: 5904 | H2: =Engagment_Summary_1[[#This Row],[New_Followers]]-Engagment_Summary_1[[#This Row],[Unfollows]] -> 1047
A3: 45446 | B3: Facebook | C3: 1312 | D3: 310 | E3: 42654 | F3: 4.98 | G3: 9566 | H3: =Engagment_Summary_1[[#This Row],[New_Followers]]-Engagment_Summary_1[[#This Row],[Unfollows]] -> 1002
A4: 45446 | B4: Twitter | C4: 584 | D4: 169 | E4: 146834 | F4: 8.31 | G4: 26752 | H4: =Engagment_Summary_1[[#This Row],[New_Followers]]-Engagment_Summary_1[[#This Row],[Unfollows]] -> 415
A5: 45446 | B5: YouTube | C5: 1535 | D5: 445 | E5: 395536 | F5: 4.11 | G5: 30671 | H5: =Engagment_Summary_1[[#This Row],[New_Followers]]-Engagment_Summary_1[[#This Row],[Unfollows]] -> 1090
A6: 45453 | B6: Instagram | C6: 656 | D6: 139 | E6: 49157 | F6: 9.05 | G6: 9920 | H6: =Engagment_Summary_1[[#This Row],[New_Followers]]-Engagment_Summary_1[[#This Row],[Unfollows]] -> 517 | J6: video link
A7: 45453 | B7: Facebook | C7: 1697 | D7: 414 | E7: 316555 | F7: 2.37 | G7: 7924 | H7: =Engagment_Summary_1[[#This Row],[New_Followers]]-Engagment_Summary_1[[#This Row],[Unfollows]] -> 1283
A8: 45453 | B8: Twitter | C8: 436 | D8: 250 | E8: 254347 | F8: 4.01 | G8: 8912 | H8: =Engagment_Summary_1[[#This Row],[New_Followers]]-Engagment_Summary_1[[#This Row],[Unfollows]] -> 186
A9: 45453 | B9: YouTube | C9: 1197 | D9: 203 | E9: 413878 | F9: 3.16 | G9: 21205 | H9: =Engagment_Summary_1[[#This Row],[New_Followers]]-Engagment_Summary_1[[#This Row],[Unfollows]] -> 994
A10: 45460 | B10: Instagram | C10: 1048 | D10: 155 | E10: 456946 | F10: 2.46 | G10: 11329 | H10: =Engagment_Summary_1[[#This Row],[New_Followers]]-Engagment_Summary_1[[#This Row],[Unfollows]] -> 893
A11: 45460 | B11: Facebook | C11: 1753 | D11: 371 | E11: 169496 | F11: 8.11 | G11: 46670 | H11: =Engagment_Summary_1[[#This Row],[New_Followers]]-Engagment_Summary_1[[#This Row],[Unfollows]] -> 1382
A12: 45460 | B12: Twitter | C12: 1335 | D12: 40 | E12: 122732 | F12: 8.19 | G12: 22482 | H12: =Engagment_Summary_1[[#This Row],[New_Followers]]-Engagment_Summary_1[[#This Row],[Unfollows]] -> 1295
A13: 45460 | B13: YouTube | C13: 403 | D13: 66 | E13: 382851 | F13: 3.49 | G13: 24313 | H13: =Engagment_Summary_1[[#This Row],[New_Followers]]-Engagment_Summary_1[[#This Row],[Unfollows]] -> 337
A14: 45467 | B14: Instagram | C14: 911 | D14: 282 | E14: 35664 | F14: 6.92 | G14: 18050 | H14: =Engagment_Summary_1[[#This Row],[New_Followers]]-Engagment_Summary_1[[#This Row],[Unfollows]] -> 629
A15: 45467 | B15: Facebook | C15: 1779 | D15: 109 | E15: 26295 | F15: 9.12 | G15: 30635 | H15: =Engagment_Summary_1[[#This Row],[New_Followers]]-Engagment_Summary_1[[#This Row],[Unfollows]] -> 1670
A16: 45467 | B16: Twitter | C16: 1238 | D16: 403 | E16: 298421 | F16: 3.5 | G16: 31280 | H16: =Engagment_Summary_1[[#This Row],[New_Followers]]-Engagment_Summary_1[[#This Row],[Unfollows]] -> 835
A17: 45467 | B17: YouTube | C17: 308 | D17: 431 | E17: 426184 | F17: 2.62 | G17: 1783 | H17: =Engagment_Summary_1[[#This Row],[New_Followers]]-Engagment_Summary_1[[#This Row],[Unfollows]] -> -123
A18: 45474 | B18: Instagram | C18: 226 | D18: 445 | E18: 419447 | F18: 9.36 | G18: 9566 | H18: =Engagment_Summary_1[[#This Row],[New_Followers]]-Engagment_Summary_1[[#This Row],[Unfollows]] -> -219
... A201: 45789 | B201: YouTube | C201: 119 | D201: 456 | E201: 82558 | F201: 6.81 | G201: 12174 | H201: =Engagment_Summary_1[[#This Row],[New_Followers]]-Engagment_Summary_1[[#This Row],[Unfollows]] -> -337

Sheet Campaign Data 
A1: Campaign_Name | B1: Start_Date | C1: End_Date | D1: Objective | E1: Total_Budget | F1: Target_Platforms
A2: EndOfSeasonSale | B2: 45453 | C2: 45478 | D2: Seasonal Clearance Promotion | E2: 180000 | F2: Instagram,Facebook
A3: FashionUpgrade | B3: 45505 | C3: 45535 | D3: Customer Engagement | E3: 160000 | F3: Instagram,YouTube
A4: MyntraFestiveEdit | B4: 45570 | C4: 45601 | D4: Festive Collection Launch | E4: 220000 | F4: Facebook,Instagram
A5: StyleRevolution | B5: 45667 | C5: 45698 | D5: Brand Awareness & Growth | E5: 200000 | F5: Instagram,Twitter | H5: video link

Sheet Post
A1: Post ID | B1: Platform | C1: Date | D1: Content Type | E1: Post Text | F1: Likes | G1: Shares | H1: Comments | I1: Impressions | J1: Reach | K1: Clicks | L1: Hashtags Used.1 | M1: Hashtags Used.2 | N1: Hashtags | O1: Campaign_Name | P1: Engagement_Rate | Q1: Total_Engagement | R1: Start_Date | S1: End_Date | T1: Campaign_Phase | V1: Task 1
A2: P001 | B2: Twitter | C2: 45649 | D2: Reel | E2: Explore the latest reel on Myntra! Trendy styles await. | F2: 1461 | G2: 184 | H2: 344 | I2: 21915 | J2: 21675 | K2: 15 | L2: MyntraSale | N2: =_xlfn.TEXTJOIN(",",TRUE,L2,M2) -> MyntraSale | O2: FashionUpgrade | P2: =(Post[[#This Row],[Likes]]+Post[[#This Row],[Shares]]+Post[[#This Row],[Comments]])/Post[[#This Row],[Impressions]] -> 0.090759754 | Q2: =F2+G2+H2 -> 1989 | R2: =_xlfn.XLOOKUP($O2,'Campaign Data '!$A:$A,'Campaign Data '!$B:$B) -> 45505 | S2: =_xlfn.XLOOKUP($O2,'Campaign Data '!$A:$A,'Campaign Data '!$C:$C) -> 45535 | T2: =+IF(AND($C2>=$R2,$C2<=$S2),"During","Before") -> Before
A3: P002 | B3: Twitter | C3: 45750 | D3: Text | E3: Explore the latest text on Myntra! Trendy styles await. | F3: 4054 | G3: 389 | H3: 493 | I3: 64864 | J3: 64383 | K3: 117 | L3: MyntraFashion | N3: =_xlfn.TEXTJOIN(",",TRUE,L3,M3) -> MyntraFashion | O3: EndOfSeasonSale | P3: =(Post[[#This Row],[Likes]]+Post[[#This Row],[Shares]]+Post[[#This Row],[Comments]])/Post[[#This Row],[Impressions]] -> 0.076097681 | Q3: =F3+G3+H3 -> 4936 | R3: =_xlfn.XLOOKUP($O3,'Campaign Data '!$A:$A,'Campaign Data '!$B:$B) -> 45453 | S3: =_xlfn.XLOOKUP($O3,'Campaign Data '!$A:$A,'Campaign Data '!$C:$C) -> 45478 | T3: =+IF(AND($C3>=$R3,$C3<=$S3),"During","Before") -> Before
A4: P003 | B4: YouTube | C4: 45789 | D4: Reel | E4: Explore the latest reel on Myntra! Trendy styles await. | F4: 2795 | G4: 105 | H4: 49 | I4: 53105 | J4: 52307 | K4: 204 | L4: MyntraFashion | M4: MyntraSale | N4: =_xlfn.TEXTJOIN(",",TRUE,L4,M4) -> MyntraFashion,MyntraSale | O4: FashionUpgrade | P4: =(Post[[#This Row],[Likes]]+Post[[#This Row],[Shares]]+Post[[#This Row],[Comments]])/Post[[#This Row],[Impressions]] -> 0.055531494 | Q4: =F4+G4+H4 -> 2949 | R4: =_xlfn.XLOOKUP($O4,'Campaign Data '!$A:$A,'Campaign Data '!$B:$B) -> 45505 | S4: =_xlfn.XLOOKUP($O4,'Campaign Data '!$A:$A,'Campaign Data '!$C:$C) -> 45535 | T4: =+IF(AND($C4>=$R4,$C4<=$S4),"During","Before") -> Before | AB4: video link
A5: P004 | B5: Instagram | C5: 45516 | D5: Story | E5: Explore the latest story on Myntra! Trendy styles await. | F5: 2404 | G5: 363 | H5: 138 | I5: 19232 | J5: 18636 | K5: 128 | L5: MyntraSale | N5: =_xlfn.TEXTJOIN(",",TRUE,L5,M5) -> MyntraSale | O5: FashionUpgrade | P5: =(Post[[#This Row],[Likes]]+Post[[#This Row],[Shares]]+Post[[#This Row],[Comments]])/Post[[#This Row],[Impressions]] -> 0.15105033 | Q5: =F5+G5+H5 -> 2905 | R5: =_xlfn.XLOOKUP($O5,'Campaign Data '!$A:$A,'Campaign Data '!$B:$B) -> 45505 | S5: =_xlfn.XLOOKUP($O5,'Campaign Data '!$A:$A,'Campaign Data '!$C:$C) -> 45535 | T5: =+IF(AND($C5>=$R5,$C5<=$S5),"During","Before") -> During
A6: P005 | B6: YouTube | C6: 45469 | D6: Reel | E6: Explore the latest reel on Myntra! Trendy styles await. | F6: 3557 | G6: 687 | H6: 424 | I6: 71140 | J6: 70701 | K6: 224 | L6: StyleWithMyntra | M6: MyntraFashion | N6: =_xlfn.TEXTJOIN(",",TRUE,L6,M6) -> StyleWithMyntra,MyntraFashion | O6: MyntraFestiveEdit | P6: =(Post[[#This Row],[Likes]]+Post[[#This Row],[Shares]]+Post[[#This Row],[Comments]])/Post[[#This Row],[Impressions]] -> 0.065617093 | Q6: =F6+G6+H6 -> 4668 | R6: =_xlfn.XLOOKUP($O6,'Campaign Data '!$A:$A,'Campaign Data '!$B:$B) -> 45570 | S6: =_xlfn.XLOOKUP($O6,'Campaign Data '!$A:$A,'Campaign Data '!$C:$C) -> 45601 | T6: =+IF(AND($C6>=$R6,$C6<=$S6),"During","Before") -> Before
A7: P006 | B7: Facebook | C7: 45596 | D7: Carousel | E7: Explore the latest carousel on Myntra! Trendy styles await. | F7: 2945 | G7: 930 | H7: 355 | I7: 23560 | J7: 23275 | K7: 256 | L7: MyntraTrend | N7: =_xlfn.TEXTJOIN(",",TRUE,L7,M7) -> MyntraTrend | O7: EndOfSeasonSale | P7: =(Post[[#This Row],[Likes]]+Post[[#This Row],[Shares]]+Post[[#This Row],[Comments]])/Post[[#This Row],[Impressions]] -> 0.1795416 | Q7: =F7+G7+H7 -> 4230 | R7: =_xlfn.XLOOKUP($O7,'Campaign Data '!$A:$A,'Campaign Data '!$B:$B) -> 45453 | S7: =_xlfn.XLOOKUP($O7,'Campaign Data '!$A:$A,'Campaign Data '!$C:$C) -> 45478 | T7: =+IF(AND($C7>=$R7,$C7<=$S7),"During","Before") -> Before
A8: P007 | B8: Twitter | C8: 45467 | D8: Carousel | E8: Explore the latest carousel on Myntra! Trendy styles await. | F8: 3860 | G8: 201 | H8: 279 | I8: 61760 | J8: 61660 | K8: 235 | L8: MyntraTrend | N8: =_xlfn.TEXTJOIN(",",TRUE,L8,M8) -> MyntraTrend | O8: MyntraFestiveEdit | P8: =(Post[[#This Row],[Likes]]+Post[[#This Row],[Shares]]+Post[[#This Row],[Comments]])/Post[[#This Row],[Impressions]] -> 0.070272021 | Q8: =F8+G8+H8 -> 4340 | R8: =_xlfn.XLOOKUP($O8,'Campaign Data '!$A:$A,'Campaign Data '!$B:$B) -> 45570 | S8: =_xlfn.XLOOKUP($O8,'Campaign Data '!$A:$A,'Campaign Data '!$C:$C) -> 45601 | T8: =+IF(AND($C8>=$R8,$C8<=$S8),"During","Before") -> Before
A9: P008 | B9: YouTube | C9: 45486 | D9: Image | E9: Explore the latest image on Myntra! Trendy styles await. | F9: 3929 | G9: 262 | H9: 278 | I9: 43219 | J9: 42841 | K9: 39 | L9: MyntraFashion | M9: MyntraSale | N9: =_xlfn.TEXTJOIN(",",TRUE,L9,M9) -> MyntraFashion,MyntraSale | O9: MyntraFestiveEdit | P9: =(Post[[#This Row],[Likes]]+Post[[#This Row],[Shares]]+Post[[#This Row],[Comments]])/Post[[#This Row],[Impressions]] -> 0.1034036 | Q9: =F9+G9+H9 -> 4469 | R9: =_xlfn.XLOOKUP($O9,'Campaign Data '!$A:$A,'Campaign Data '!$B:$B) -> 45570 | S9: =_xlfn.XLOOKUP($O9,'Campaign Data '!$A:$A,'Campaign Data '!$C:$C) -> 45601 | T9: =+IF(AND($C9>=$R9,$C9<=$S9),"During","Before") -> Before
A10: P009 | B10: Facebook | C10: 45534 | D10: Text | E10: Explore the latest text on Myntra! Trendy styles await. | F10: 3784 | G10: 808 | H10: 404 | I10: 56760 | J10: 56343 | K10: 131 | L10: MyntraFashion | M10: MyntraSale | N10: =_xlfn.TEXTJOIN(",",TRUE,L10,M10) -> MyntraFashion,MyntraSale | O10: MyntraFestiveEdit | P10: =(Post[[#This Row],[Likes]]+Post[[#This Row],[Shares]]+Post[[#This Row],[Comments]])/Post[[#This Row],[Impressions]] -> 0.088019732 | Q10: =F10+G10+H10 -> 4996 | R10: =_xlfn.XLOOKUP($O10,'Campaign Data '!$A:$A,'Campaign Data '!$B:$B) -> 45570 | S10: =_xlfn.XLOOKUP($O10,'Campaign Data '!$A:$A,'Campaign Data '!$C:$C) -> 45601 | T10: =+IF(AND($C10>=$R10,$C10<=$S10),"During","Before") -> Before
A11: P010 | B11: Facebook | C11: 45727 | D11: Image | E11: Explore the latest image on Myntra! Trendy styles await. | F11: 4241 | G11: 902 | H11: 47 | I11: 72097 | J11: 71598 | K11: 167 | L11: MyntraTrend | N11: =_xlfn.TEXTJOIN(",",TRUE,L11,M11) -> MyntraTrend | O11: StyleRevolution | P11: =(Post[[#This Row],[Likes]]+Post[[#This Row],[Shares]]+Post[[#This Row],[Comments]])/Post[[#This Row],[Impressions]] -> 0.071986352 | Q11: =F11+G11+H11 -> 5190 | R11: =_xlfn.XLOOKUP($O11,'Campaign Data '!$A:$A,'Campaign Data '!$B:$B) -> 45667 | S11: =_xlfn.XLOOKUP($O11,'Campaign Data '!$A:$A,'Campaign Data '!$C:$C) -> 45698 | T11: =+IF(AND($C11>=$R11,$C11<=$S11),"During","Before") -> Before
A12: P011 | B12: Instagram | C12: 45690 | D12: Story | E12: Explore the latest story on Myntra! Trendy styles await. | F12: 1792 | G12: 614 | H12: 497 | I12: 25088 | J12: 24675 | K12: 65 | L12: StyleWithMyntra | N12: =_xlfn.TEXTJOIN(",",TRUE,L12,M12) -> StyleWithMyntra | O12: FashionUpgrade | P12: =(Post[[#This Row],[Likes]]+Post[[#This Row],[Shares]]+Post[[#This Row],[Comments]])/Post[[#This Row],[Impressions]] -> 0.11571269 | Q12: =F12+G12+H12 -> 2903 | R12: =_xlfn.XLOOKUP($O12,'Campaign Data '!$A:$A,'Campaign Data '!$B:$B) -> 45505 | S12: =_xlfn.XLOOKUP($O12,'Campaign Data '!$A:$A,'Campaign Data '!$C:$C) -> 45535 | T12: =+IF(AND($C12>=$R12,$C12<=$S12),"During","Before") -> Before
A13: P012 | B13: Facebook | C13: 45494 | D13: Reel | E13: Explore the latest reel on Myntra! Trendy styles await. | F13: 1946 | G13: 686 | H13: 377 | I13: 23352 | J13: 22982 | K13: 213 | L13: StyleWithMyntra | M13: MyntraSale | N13: =_xlfn.TEXTJOIN(",",TRUE,L13,M13) -> StyleWithMyntra,MyntraSale | O13: MyntraFestiveEdit | P13: =(Post[[#This Row],[Likes]]+Post[[#This Row],[Shares]]+Post[[#This Row],[Comments]])/Post[[#This Row],[Impressions]] -> 0.12885406 | Q13: =F13+G13+H13 -> 3009 | R13: =_xlfn.XLOOKUP($O13,'Campaign Data '!$A:$A,'Campaign Data '!$B:$B) -> 45570 | S13: =_xlfn.XLOOKUP($O13,'Campaign Data '!$A:$A,'Campaign Data '!$C:$C) -> 45601 | T13: =+IF(AND($C13>=$R13,$C13<=$S13),"During","Before") -> Before
A14: P013 | B14: YouTube | C14: 45614 | D14: Carousel | E14: Explore the latest carousel on Myntra! Trendy styles await. | F14: 1171 | G14: 286 | H14: 231 | I14: 22249 | J14: 21282 | K14: 114 | L14: MyntraFashion | N14: =_xlfn.TEXTJOIN(",",TRUE,L14,M14) -> MyntraFashion | O14: StyleRevolution | P14: =(Post[[#This Row],[Likes]]+Post[[#This Row],[Shares]]+Post[[#This Row],[Comments]])/Post[[#This Row],[Impressions]] -> 0.075868578 | Q14: =F14+G14+H14 -> 1688 | R14: =_xlfn.XLOOKUP($O14,'Campaign Data '!$A:$A,'Campaign Data '!$B:$B) -> 45667 | S14: =_xlfn.XLOOKUP($O14,'Campaign Data '!$A:$A,'Campaign Data '!$C:$C) -> 45698 | T14: =+IF(AND($C14>=$R14,$C14<=$S14),"During","Before") -> Before | V14: Observed: Duplicate posts Inconsistent date format Mixed platform naming Hashtags bundled together Actions taken: Removed duplicates Standardized formats Cleaned numeric fields Split hashtags into individual tags Result: A trustworthy dataset ready for analysis
A15: P014 | B15: Facebook | C15: 45704 | D15: Story | E15: Explore the latest story on Myntra! Trendy styles await. | F15: 4242 | G15: 555 | H15: 131 | I15: 33936 | J15: 33802 | K15: 265 | L15: MyntraSale | M15: MyntraFashion | N15: =_xlfn.TEXTJOIN(",",TRUE,L15,M15) -> MyntraSale,MyntraFashion | O15: MyntraFestiveEdit | P15: =(Post[[#This Row],[Likes]]+Post[[#This Row],[Shares]]+Post[[#This Row],[Comments]])/Post[[#This Row],[Impressions]] -> 0.14521452 | Q15: =F15+G15+H15 -> 4928 | R15: =_xlfn.XLOOKUP($O15,'Campaign Data '!$A:$A,'Campaign Data '!$B:$B) -> 45570 | S15: =_xlfn.XLOOKUP($O15,'Campaign Data '!$A:$A,'Campaign Data '!$C:$C) -> 45601 | T15: =+IF(AND($C15>=$R15,$C15<=$S15),"During","Before") -> Before
A16: P015 | B16: Facebook | C16: 45589 | D16: Video | E16: Explore the latest video on Myntra! Trendy styles await. | F16: 3888 | G16: 604 | H16: 128 | I16: 77760 | J16: 77167 | K16: 20 | L16: MyntraFashion | M16: FashionDeals | N16: =_xlfn.TEXTJOIN(",",TRUE,L16,M16) -> MyntraFashion,FashionDeals | O16: FashionUpgrade | P16: =(Post[[#This Row],[Likes]]+Post[[#This Row],[Shares]]+Post[[#This Row],[Comments]])/Post[[#This Row],[Impressions]] -> 0.05941358 | Q16: =F16+G16+H16 -> 4620 | R16: =_xlfn.XLOOKUP($O16,'Campaign Data '!$A:$A,'Campaign Data '!$B:$B) -> 45505 | S16: =_xlfn.XLOOKUP($O16,'Campaign Data '!$A:$A,'Campaign Data '!$C:$C) -> 45535 | T16: =+IF(AND($C16>=$R16,$C16<=$S16),"During","Before") -> Before
A17: P016 | B17: Facebook | C17: 45530 | D17: Text | E17: Explore the latest text on Myntra! Trendy styles await. | F17: 3452 | G17: 377 | H17: 360 | I17: 55232 | J17: 55075 | K17: 87 | L17: MyntraSale | M17: FashionDeals | N17: =_xlfn.TEXTJOIN(",",TRUE,L17,M17) -> MyntraSale,FashionDeals | O17: MyntraFestiveEdit | P17: =(Post[[#This Row],[Likes]]+Post[[#This Row],[Shares]]+Post[[#This Row],[Comments]])/Post[[#This Row],[Impressions]] -> 0.075843714 | Q17: =F17+G17+H17 -> 4189 | R17: =_xlfn.XLOOKUP($O17,'Campaign Data '!$A:$A,'Campaign Data '!$B:$B) -> 45570 | S17: =_xlfn.XLOOKUP($O17,'Campaign Data '!$A:$A,'Campaign Data '!$C:$C) -> 45601 | T17: =+IF(AND($C17>=$R17,$C17<=$S17),"During","Before") -> Before
A18: P017 | B18: Facebook | C18: 45782 | D18: Text | E18: Explore the latest text on Myntra! Trendy styles await. | F18: 4441 | G18: 511 | H18: 70 | I18: 53292 | J18: 53082 | K18: 159 | L18: FashionDeals | N18: =_xlfn.TEXTJOIN(",",TRUE,L18,M18) -> FashionDeals | O18: MyntraFestiveEdit | P18: =(Post[[#This Row],[Likes]]+Post[[#This Row],[Shares]]+Post[[#This Row],[Comments]])/Post[[#This Row],[Impressions]] -> 0.094235533 | Q18: =F18+G18+H18 -> 5022 | R18: =_xlfn.XLOOKUP($O18,'Campaign Data '!$A:$A,'Campaign Data '!$B:$B) -> 45570 | S18: =_xlfn.XLOOKUP($O18,'Campaign Data '!$A:$A,'Campaign Data '!$C:$C) -> 45601 | T18: =+IF(AND($C18>=$R18,$C18<=$S18),"During","Before") -> Before
A19: P018 | B19: Instagram | C19: 45523 | D19: Reel | E19: Explore the latest reel on Myntra! Trendy styles await. | F19: 3000 | G19: 382 | H19: 325 | I19: 36000 | J19: 35819 | K19: 19 | L19: StyleWithMyntra | N19: =_xlfn.TEXTJOIN(",",TRUE,L19,M19) -> StyleWithMyntra | O19: EndOfSeasonSale | P19: =(Post[[#This Row],[Likes]]+Post[[#This Row],[Shares]]+Post[[#This Row],[Comments]])/Post[[#This Row],[Impressions]] -> 0.10297222 | Q19: =F19+G19+H19 -> 3707 | R19: =_xlfn.XLOOKUP($O19,'Campaign Data '!$A:$A,'Campaign Data '!$B:$B) -> 45453 | S19: =_xlfn.XLOOKUP($O19,'Campaign Data '!$A:$A,'Campaign Data '!$C:$C) -> 45478 | T19: =+IF(AND($C19>=$R19,$C19<=$S19),"During","Before") -> Before
A20: P019 | B20: Instagram | C20: 45466 | D20: Video | E20: Explore the latest video on Myntra! Trendy styles await. | F20: 1071 | G20: 519 | H20: 22 | I20: 16065 | J20: 15865 | K20: 103 | L20: MyntraSale | M20: StyleWithMyntra | N20: =_xlfn.TEXTJOIN(",",TRUE,L20,M20) -> MyntraSale,StyleWithMyntra | O20: MyntraFestiveEdit | P20: =(Post[[#This Row],[Likes]]+Post[[#This Row],[Shares]]+Post[[#This Row],[Comments]])/Post[[#This Row],[Impressions]] -> 0.10034236 | Q20: =F20+G20+H20 -> 1612 | R20: =_xlfn.XLOOKUP($O20,'Campaign Data '!$A:$A,'Campaign Data '!$B:$B) -> 45570 | S20: =_xlfn.XLOOKUP($O20,'Campaign Data '!$A:$A,'Campaign Data '!$C:$C) -> 45601 | T20: =+IF(AND($C20>=$R20,$C20<=$S20),"During","Before") -> Before
A21: P020 | B21: Instagram | C21: 45544 | D21: Carousel | E21: Explore the latest carousel on Myntra! Trendy styles await. | F21: 4054 | G21: 488 | H21: 373 | I21: 77026 | J21: 76881 | K21: 25 | L21: MyntraFashion | M21: MyntraSale | N21: =_xlfn.TEXTJOIN(",",TRUE,L21,M21) -> MyntraFashion,MyntraSale | O21: MyntraFestiveEdit | P21: =(Post[[#This Row],[Likes]]+Post[[#This Row],[Shares]]+Post[[#This Row],[Comments]])/Post[[#This Row],[Impressions]] -> 0.063809623 | Q21: =F21+G21+H21 -> 4915 | R21: =_xlfn.XLOOKUP($O21,'Campaign Data '!$A:$A,'Campaign Data '!$B:$B) -> 45570 | S21: =_xlfn.XLOOKUP($O21,'Campaign Data '!$A:$A,'Campaign Data '!$C:$C) -> 45601 | T21: =+IF(AND($C21>=$R21,$C21<=$S21),"During","Before") -> Before
A22: P021 | B22: Instagram | C22: 45661 | D22: Reel | E22: Explore the latest reel on Myntra! Trendy styles await. | F22: 4838 | G22: 640 | H22: 128 | I22: 72570 | J22: 72396 | K22: 83 | L22: StyleWithMyntra | M22: MyntraTrend | N22: =_xlfn.TEXTJOIN(",",TRUE,L22,M22) -> StyleWithMyntra,MyntraTrend | O22: MyntraFestiveEdit | P22: =(Post[[#This Row],[Likes]]+Post[[#This Row],[Shares]]+Post[[#This Row],[Comments]])/Post[[#This Row],[Impressions]] -> 0.077249552 | Q22: =F22+G22+H22 -> 5606 | R22: =_xlfn.XLOOKUP($O22,'Campaign Data '!$A:$A,'Campaign Data '!$B:$B) -> 45570 | S22: =_xlfn.XLOOKUP($O22,'Campaign Data '!$A:$A,'Campaign Data '!$C:$C) -> 45601 | T22: =+IF(AND($C22>=$R22,$C22<=$S22),"During","Before") -> Before
A23: P022 | B23: Facebook | C23: 45715 | D23: Text | E23: Explore the latest text on Myntra! Trendy styles await. | F23: 1570 | G23: 187 | H23: 260 | I23: 25120 | J23: 24613 | K23: 133 | L23: MyntraSale | N23: =_xlfn.TEXTJOIN(",",TRUE,L23,M23) -> MyntraSale | O23: StyleRevolution | P23: =(Post[[#This Row],[Likes]]+Post[[#This Row],[Shares]]+Post[[#This Row],[Comments]])/Post[[#This Row],[Impressions]] -> 0.080294586 | Q23: =F23+G23+H23 -> 2017 | R23: =_xlfn.XLOOKUP($O23,'Campaign Data '!$A:$A,'Campaign Data '!$B:$B) -> 45667 | S23: =_xlfn.XLOOKUP($O23,'Campaign Data '!$A:$A,'Campaign Data '!$C:$C) -> 45698 | T23: =+IF(AND($C23>=$R23,$C23<=$S23),"During","Before") -> Before
A24: P023 | B24: Facebook | C24: 45602 | D24: Video | E24: Explore the latest video on Myntra! Trendy styles await. | F24: 1606 | G24: 547 | H24: 316 | I24: 32120 | J24: 31736 | K24: 225 | L24: MyntraSale | N24: =_xlfn.TEXTJOIN(",",TRUE,L24,M24) -> MyntraSale | O24: MyntraFestiveEdit | P24: =(Post[[#This Row],[Likes]]+Post[[#This Row],[Shares]]+Post[[#This Row],[Comments]])/Post[[#This Row],[Impressions]] -> 0.076867995 | Q24: =F24+G24+H24 -> 2469 | R24: =_xlfn.XLOOKUP($O24,'Campaign Data '!$A:$A,'Campaign Data '!$B:$B) -> 45570 | S24: =_xlfn.XLOOKUP($O24,'Campaign Data '!$A:$A,'Campaign Data '!$C:$C) -> 45601 | T24: =+IF(AND($C24>=$R24,$C24<=$S24),"During","Before") -> Before
A25: P024 | B25: Facebook | C25: 45680 | D25: Video | E25: Explore the latest video on Myntra! Trendy styles await. | F25: 3961 | G25: 761 | H25: 131 | I25: 67337 | J25: 66615 | K25: 161 | L25: MyntraTrend | N25: =_xlfn.TEXTJOIN(",",TRUE,L25,M25) -> MyntraTrend | O25: EndOfSeasonSale | P25: =(Post[[#This Row],[Likes]]+Post[[#This Row],[Shares]]+Post[[#This Row],[Comments]])/Post[[#This Row],[Impressions]] -> 0.072070333 | Q25: =F25+G25+H25 -> 4853 | R25: =_xlfn.XLOOKUP($O25,'Campaign Data '!$A:$A,'Campaign Data '!$B:$B) -> 45453 | S25: =_xlfn.XLOOKUP($O25,'Campaign Data '!$A:$A,'Campaign Data '!$C:$C) -> 45478 | T25: =+IF(AND($C25>=$R25,$C25<=$S25),"During","Before") -> Before
A26: P025 | B26: Twitter | C26: 45757 | D26: Carousel | E26: Explore the latest carousel on Myntra! Trendy styles await. | F26: 3128 | G26: 211 | H26: 197 | I26: 59432 | J26: 59182 | K26: 238 | L26: StyleWithMyntra | M26: MyntraSale | N26: =_xlfn.TEXTJOIN(",",TRUE,L26,M26) -> StyleWithMyntra,MyntraSale | O26: FashionUpgrade | P26: =(Post[[#This Row],[Likes]]+Post[[#This Row],[Shares]]+Post[[#This Row],[Comments]])/Post[[#This Row],[Impressions]] -> 0.059496568 | Q26: =F26+G26+H26 -> 3536 | R26: =_xlfn.XLOOKUP($O26,'Campaign Data '!$A:$A,'Campaign Data '!$B:$B) -> 45505 | S26: =_xlfn.XLOOKUP($O26,'Campaign Data '!$A:$A,'Campaign Data '!$C:$C) -> 45535 | T26: =+IF(AND($C26>=$R26,$C26<=$S26),"During","Before") -> Before
A27: P026 | B27: YouTube | C27: 45752 | D27: Reel | E27: Explore the latest reel on Myntra! Trendy styles await. | F27: 3009 | G27: 413 | H27: 358 | I27: 42126 | J27: 41309 | K27: 211 | L27: MyntraSale | N27: =_xlfn.TEXTJOIN(",",TRUE,L27,M27) -> MyntraSale | O27: EndOfSeasonSale | P27: =(Post[[#This Row],[Likes]]+Post[[#This Row],[Shares]]+Post[[#This Row],[Comments]])/Post[[#This Row],[Impressions]] -> 0.089730808 | Q27: =F27+G27+H27 -> 3780 | R27: =_xlfn.XLOOKUP($O27,'Campaign Data '!$A:$A,'Campaign Data '!$B:$B) -> 45453 | S27: =_xlfn.XLOOKUP($O27,'Campaign Data '!$A:$A,'Campaign Data '!$C:$C) -> 45478 | T27: =+IF(AND($C27>=$R27,$C27<=$S27),"During","Before") -> Before
A28: P027 | B28: YouTube | C28: 45552 | D28: Text | E28: Explore the latest text on Myntra! Trendy styles await. | F28: 2076 | G28: 195 | H28: 104 | I28: 33216 | J28: 32244 | K28: 51 | L28: MyntraTrend | N28: =_xlfn.TEXTJOIN(",",TRUE,L28,M28) -> MyntraTrend | O28: StyleRevolution | P28: =(Post[[#This Row],[Likes]]+Post[[#This Row],[Shares]]+Post[[#This Row],[Comments]])/Post[[#This Row],[Impressions]] -> 0.071501686 | Q28: =F28+G28+H28 -> 2375 | R28: =_xlfn.XLOOKUP($O28,'Campaign Data '!$A:$A,'Campaign Data '!$B:$B) -> 45667 | S28: =_xlfn.XLOOKUP($O28,'Campaign Data '!$A:$A,'Campaign Data '!$C:$C) -> 45698 | T28: =+IF(AND($C28>=$R28,$C28<=$S28),"During","Before") -> Before
A29: P028 | B29: Instagram | C29: 45720 | D29: Video | E29: Explore the latest video on Myntra! Trendy styles await. | F29: 432 | G29: 624 | H29: 123 | I29: 6912 | J29: 6259 | K29: 79 | L29: MyntraSale | M29: MyntraTrend | N29: =_xlfn.TEXTJOIN(",",TRUE,L29,M29) -> MyntraSale,MyntraTrend | O29: EndOfSeasonSale | P29: =(Post[[#This Row],[Likes]]+Post[[#This Row],[Shares]]+Post[[#This Row],[Comments]])/Post[[#This Row],[Impressions]] -> 0.17057292 | Q29: =F29+G29+H29 -> 1179 | R29: =_xlfn.XLOOKUP($O29,'Campaign Data '!$A:$A,'Campaign Data '!$B:$B) -> 45453 | S29: =_xlfn.XLOOKUP($O29,'Campaign Data '!$A:$A,'Campaign Data '!$C:$C) -> 45478 | T29: =+IF(AND($C29>=$R29,$C29<=$S29),"During","Before") -> Before
A30: P029 | B30: Instagram | C30: 45688 | D30: Carousel | E30: Explore the latest carousel on Myntra! Trendy styles await. | F30: 2566 | G30: 118 | H30: 37 | I30: 12830 | J30: 12264 | K30: 221 | L30: MyntraTrend | M30: MyntraFashion | N30: =_xlfn.TEXTJOIN(",",TRUE,L30,M30) -> MyntraTrend,MyntraFashion | O30: MyntraFestiveEdit | P30: =(Post[[#This Row],[Likes]]+Post[[#This Row],[Shares]]+Post[[#This Row],[Comments]])/Post[[#This Row],[Impressions]] -> 0.21208106 | Q30: =F30+G30+H30 -> 2721 | R30: =_xlfn.XLOOKUP($O30,'Campaign Data '!$A:$A,'Campaign Data '!$B:$B) -> 45570 | S30: =_xlfn.XLOOKUP($O30,'Campaign Data '!$A:$A,'Campaign Data '!$C:$C) -> 45601 | T30: =+IF(AND($C30>=$R30,$C30<=$S30),"During","Before") -> Before
A31: P030 | B31: Instagram | C31: 45713 | D31: Video | E31: Explore the latest video on Myntra! Trendy styles await. | F31: 3095 | G31: 39 | H31: 78 | I31: 55710 | J31: 54808 | K31: 93 | L31: MyntraSale | N31: =_xlfn.TEXTJOIN(",",TRUE,L31,M31) -> MyntraSale | O31: StyleRevolution | P31: =(Post[[#This Row],[Likes]]+Post[[#This Row],[Shares]]+Post[[#This Row],[Comments]])/Post[[#This Row],[Impressions]] -> 0.057655717 | Q31: =F31+G31+H31 -> 3212 | R31: =_xlfn.XLOOKUP($O31,'Campaign Data '!$A:$A,'Campaign Data '!$B:$B) -> 45667 | S31: =_xlfn.XLOOKUP($O31,'Campaign Data '!$A:$A,'Campaign Data '!$C:$C) -> 45698 | T31: =+IF(AND($C31>=$R31,$C31<=$S31),"During","Before") -> Before
A32: P031 | B32: Instagram | C32: 45642 | D32: Text | E32: Explore the latest text on Myntra! Trendy styles await. | F32: 438 | G32: 153 | H32: 275 | I32: 3066 | J32: 2701 | K32: 282 | L32: MyntraTrend | N32: =_xlfn.TEXTJOIN(",",TRUE,L32,M32) -> MyntraTrend | O32: StyleRevolution | P32: =(Post[[#This Row],[Likes]]+Post[[#This Row],[Shares]]+Post[[#This Row],[Comments]])/Post[[#This Row],[Impressions]] -> 0.28245271 | Q32: =F32+G32+H32 -> 866 | R32: =_xlfn.XLOOKUP($O32,'Campaign Data '!$A:$A,'Campaign Data '!$B:$B) -> 45667 | S32: =_xlfn.XLOOKUP($O32,'Campaign Data '!$A:$A,'Campaign Data '!$C:$C) -> 45698 | T32: =+IF(AND($C32>=$R32,$C32<=$S32),"During","Before") -> Before
A33: P032 | B33: Twitter | C33: 45504 | D33: Carousel | E33: Explore the latest carousel on Myntra! Trendy styles await. | F33: 2278 | G33: 10 | H33: 321 | I33: 13668 | J33: 12676 | K33: 275 | L33: MyntraTrend | M33: MyntraFashion | N33: =_xlfn.TEXTJOIN(",",TRUE,L33,M33) -> MyntraTrend,MyntraFashion | O33: StyleRevolution | P33: =(Post[[#This Row],[Likes]]+Post[[#This Row],[Shares]]+Post[[#This Row],[Comments]])/Post[[#This Row],[Impressions]] -> 0.19088382 | Q33: =F33+G33+H33 -> 2609 | R33: =_xlfn.XLOOKUP($O33,'Campaign Data '!$A:$A,'Campaign Data '!$B:$B) -> 45667 | S33: =_xlfn.XLOOKUP($O33,'Campaign Data '!$A:$A,'Campaign Data '!$C:$C) -> 45698 | T33: =+IF(AND($C33>=$R33,$C33<=$S33),"During","Before") -> Before
A34: P033 | B34: Facebook | C34: 45525 | D34: Image | E34: Explore the latest image on Myntra! Trendy styles await. | F34: 1407 | G34: 400 | H34: 351 | I34: 16884 | J34: 15954 | K34: 113 | L34: MyntraFashion | M34: FashionDeals | N34: =_xlfn.TEXTJOIN(",",TRUE,L34,M34) -> MyntraFashion,FashionDeals | O34: MyntraFestiveEdit | P34: =(Post[[#This Row],[Likes]]+Post[[#This Row],[Shares]]+Post[[#This Row],[Comments]])/Post[[#This Row],[Impressions]] -> 0.12781331 | Q34: =F34+G34+H34 -> 2158 | R34: =_xlfn.XLOOKUP($O34,'Campaign Data '!$A:$A,'Campaign Data '!$B:$B) -> 45570 | S34: =_xlfn.XLOOKUP($O34,'Campaign Data '!$A:$A,'Campaign Data '!$C:$C) -> 45601 | T34: =+IF(AND($C34>=$R34,$C34<=$S34),"During","Before") -> Before
A35: P034 | B35: Facebook | C35: 45742 | D35: Text | E35: Explore the latest text on Myntra! Trendy styles await. | F35: 1652 | G35: 89 | H35: 357 | I35: 29736 | J35: 28771 | K35: 215 | L35: MyntraTrend | M35: FashionDeals | N35: =_xlfn.TEXTJOIN(",",TRUE,L35,M35) -> MyntraTrend,FashionDeals | O35: EndOfSeasonSale | P35: =(Post[[#This Row],[Likes]]+Post[[#This Row],[Shares]]+Post[[#This Row],[Comments]])/Post[[#This Row],[Impressions]] -> 0.07055421 | Q35: =F35+G35+H35 -> 2098 | R35: =_xlfn.XLOOKUP($O35,'Campaign Data '!$A:$A,'Campaign Data '!$B:$B) -> 45453 | S35: =_xlfn.XLOOKUP($O35,'Campaign Data '!$A:$A,'Campaign Data '!$C:$C) -> 45478 | T35: =+IF(AND($C35>=$R35,$C35<=$S35),"During","Before") -> Before
A36: P035 | B36: Instagram | C36: 45626 | D36: Video | E36: Explore the latest video on Myntra! Trendy styles await. | F36: 3775 | G36: 16 | H36: 239 | I36: 33975 | J36: 33310 | K36: 271 | L36: StyleWithMyntra | M36: MyntraSale | N36: =_xlfn.TEXTJOIN(",",TRUE,L36,M36) -> StyleWithMyntra,MyntraSale | O36: MyntraFestiveEdit | P36: =(Post[[#This Row],[Likes]]+Post[[#This Row],[Shares]]+Post[[#This Row],[Comments]])/Post[[#This Row],[Impressions]] -> 0.11861663 | Q36: =F36+G36+H36 -> 4030 | R36: =_xlfn.XLOOKUP($O36,'Campaign Data '!$A:$A,'Campaign Data '!$B:$B) -> 45570 | S36: =_xlfn.XLOOKUP($O36,'Campaign Data '!$A:$A,'Campaign Data '!$C:$C) -> 45601 | T36: =+IF(AND($C36>=$R36,$C36<=$S36),"During","Before") -> Before
A37: P036 | B37: Instagram | C37: 45766 | D37: Story | E37: Explore the latest story on Myntra! Trendy styles await. | F37: 4518 | G37: 285 | H37: 383 | I37: 67770 | J37: 67621 | K37: 31 | L37: FashionDeals | N37: =_xlfn.TEXTJOIN(",",TRUE,L37,M37) -> FashionDeals | O37: EndOfSeasonSale | P37: =(Post[[#This Row],[Likes]]+Post[[#This Row],[Shares]]+Post[[#This Row],[Comments]])/Post[[#This Row],[Impressions]] -> 0.076523535 | Q37: =F37+G37+H37 -> 5186 | R37: =_xlfn.XLOOKUP($O37,'Campaign Data '!$A:$A,'Campaign Data '!$B:$B) -> 45453 | S37: =_xlfn.XLOOKUP($O37,'Campaign Data '!$A:$A,'Campaign Data '!$C:$C) -> 45478 | T37: =+IF(AND($C37>=$R37,$C37<=$S37),"During","Before") -> Before
A38: P037 | B38: Facebook | C38: 45663 | D38: Carousel | E38: Explore the latest carousel on Myntra! Trendy styles await. | F38: 3024 | G38: 925 | H38: 350 | I38: 24192 | J38: 23518 | K38: 36 | L38: MyntraSale | N38: =_xlfn.TEXTJOIN(",",TRUE,L38,M38) -> MyntraSale | O38: MyntraFestiveEdit | P38: =(Post[[#This Row],[Likes]]+Post[[#This Row],[Shares]]+Post[[#This Row],[Comments]])/Post[[#This Row],[Impressions]] -> 0.17770337 | Q38: =F38+G38+H38 -> 4299 | R38: =_xlfn.XLOOKUP($O38,'Campaign Data '!$A:$A,'Campaign Data '!$B:$B) -> 45570 | S38: =_xlfn.XLOOKUP($O38,'Campaign Data '!$A:$A,'Campaign Data '!$C:$C) -> 45601 | T38: =+IF(AND($C38>=$R38,$C38<=$S38),"During","Before") -> Before
A39: P038 | B39: YouTube | C39: 45705 | D39: Reel | E39: Explore the latest reel on Myntra! Trendy styles await. | F39: 3138 | G39: 123 | H39: 291 | I39: 28242 | J39: 27550 | K39: 87 | L39: FashionDeals | N39: =_xlfn.TEXTJOIN(",",TRUE,L39,M39) -> FashionDeals | O39: StyleRevolution | P39: =(Post[[#This Row],[Likes]]+Post[[#This Row],[Shares]]+Post[[#This Row],[Comments]])/Post[[#This Row],[Impressions]] -> 0.12577013 | Q39: =F39+G39+H39 -> 3552 | R39: =_xlfn.XLOOKUP($O39,'Campaign Data '!$A:$A,'Campaign Data '!$B:$B) -> 45667 | S39: =_xlfn.XLOOKUP($O39,'Campaign Data '!$A:$A,'Campaign Data '!$C:$C) -> 45698 | T39: =+IF(AND($C39>=$R39,$C39<=$S39),"During","Before") -> Before
A40: P039 | B40: Facebook | C40: 45621 | D40: Image | E40: Explore the latest image on Myntra! Trendy styles await. | F40: 3564 | G40: 629 | H40: 177 | I40: 60588 | J40: 59627 | K40: 92 | L40: FashionDeals | M40: MyntraSale | N40: =_xlfn.TEXTJOIN(",",TRUE,L40,M40) -> FashionDeals,MyntraSale | O40: MyntraFestiveEdit | P40: =(Post[[#This Row],[Likes]]+Post[[#This Row],[Shares]]+Post[[#This Row],[Comments]])/Post[[#This Row],[Impressions]] -> 0.072126494 | Q40: =F40+G40+H40 -> 4370 | R40: =_xlfn.XLOOKUP($O40,'Campaign Data '!$A:$A,'Campaign Data '!$B:$B) -> 45570 | S40: =_xlfn.XLOOKUP($O40,'Campaign Data '!$A:$A,'Campaign Data '!$C:$C) -> 45601 | T40: =+IF(AND($C40>=$R40,$C40<=$S40),"During","Before") -> Before
...

Sheet 2.Engagement Analysis 
A1: Task- 2 | F1: Task -2
C8: Top 10 Engagment Post | E8: Total Likes ,Shares ,comments by content Type and Platform
C9: top 10 | F9: Playform
C10: 1.8129 | F10: Facebook | I10: Instagram | L10: Twitter | O10: YouTube | R10: Total Sum of Likes | S10: Total Sum of Shares | T10: Total Sum of Comments
C11: 0.866 | E11: Content Type | F11: Sum of Likes | G11: Sum of Shares | H11: Sum of Comments | I11: Sum of Likes | J11: Sum of Shares | K11: Sum of Comments | L11: Sum of Likes | M11: Sum of Shares | N11: Sum of Comments | O11: Sum of Likes | P11: Sum of Shares | Q11: Sum of Comments
C12: 0.7169 | E12: Carousel | F12: 44476 | G12: 7400 | H12: 4589 | I12: 43948 | J12: 6975 | K12: 3890 | L12: 48649 | M12: 5791 | N12: 3607 | O12: 24926 | P12: 6305 | Q12: 2422 | R12: 161999 | S12: 26471 | T12: 14508
C13: 0.7039 | E13: Image | F13: 71602 | G13: 12904 | H13: 6495 | I13: 34202 | J13: 5286 | K13: 2655 | L13: 43761 | M13: 7110 | N13: 5125 | O13: 23903 | P13: 4310 | Q13: 2077 | R13: 173468 | S13: 29610 | T13: 16352
C14: 0.6508 | E14: Reel | F14: 36368 | G14: 5964 | H14: 3353 | I14: 32148 | J14: 8110 | K14: 3386 | L14: 27029 | M14: 4550 | N14: 1913 | O14: 32400 | P14: 4577 | Q14: 2668 | R14: 127945 | S14: 23201 | T14: 11320
C15: 0.5377 | E15: Story | F15: 29405 | G15: 4950 | H15: 3223 | I15: 42649 | J15: 10049 | K15: 3846 | L15: 20466 | M15: 5090 | N15: 3026 | O15: 31968 | P15: 3866 | Q15: 2012 | R15: 124488 | S15: 23955 | T15: 12107
C16: 0.5339 | E16: Text | F16: 31963 | G16: 4792 | H16: 3377 | I16: 25567 | J16: 5112 | K16: 1946 | L16: 31899 | M16: 4861 | N16: 3910 | O16: 27067 | P16: 3928 | Q16: 1052 | R16: 116496 | S16: 18693 | T16: 10285
C17: 0.5019 | E17: Video | F17: 28947 | G17: 3171 | H17: 2263 | I17: 25770 | J17: 5912 | K17: 2128 | L17: 29593 | M17: 6326 | N17: 3299 | O17: 31285 | P17: 5586 | Q17: 2589 | R17: 115595 | S17: 20995 | T17: 10279
C18: 0.4852 | E18: Grand Total | F18: 242761 | G18: 39181 | H18: 23300 | I18: 204284 | J18: 41444 | K18: 17851 | L18: 201397 | M18: 33728 | N18: 20880 | O18: 171549 | P18: 28572 | Q18: 12820 | R18: 819991 | S18: 142925 | T18: 74851
C19: 0.3827
C24: Avg Clicks | F24: Average Engagement rate | K24: video link
C25: Platform | D25: Average of Clicks | F25: Platform | G25: Average of Clicks
C26: Twitter | D26: 156.93671 | F26: FashionDeals | G26: 159.76
C27: Instagram | D27: 152.88608 | F27: MyntraFashion | G27: 141.34545
C28: YouTube | D28: 147.55932 | F28: MyntraSale | G28: 145.92754
C29: Facebook | D29: 146.79518 | F29: MyntraTrend | G29: 170.23333
C30: Grand Total | D30: 151.22 | F30: StyleWithMyntra | G30: 141.22727

Sheet 3.Platform Analysis 
A1: Task- 3
B7: PLATFORM | C7: Engagement_Rat
B8: Facebook | C8: 5.6486
B9: Instagram | C9: 5.7156
B10: Twitter | C10: 5.6558
B11: YouTube | C11: 5.5588
I24: platform | J24: Followers_Growth
I25: Facebook | J25: 35557
I26: Instagram | J26: 48004
I27: Twitter | J27: 41177
I28: YouTube | J28: 35367
I29: Grand Total | J29: 160105
I33: Platform | J33: Average of Follower_Growth | K33: Average of Ad_Spend
I34: Facebook | J34: 711.14 | K34: 27590.78
I35: Instagram | J35: 960.08 | K35: 23287.46
I36: Twitter | J36: 823.54 | K36: 21207.14
I37: YouTube | J37: 707.34 | K37: 24572.94
I38: Grand Total | J38: 800.525 | K38: 24164.58
B45: Myntra should follow a multi-platform strategy with Instagram as the primary engagement channel, supported by Twitter, YouTube and Facebook based on platform strengths.
J46: video link

Sheet 4.Hashtag Analysis
A1: Task- 4
C7: Most Frq Used Hastags | F7: AVERAGE PERFORMANCE OF POSTS CONTAINING EACH HASHTAG
C8: Hashtags Used 1 | D8: Count of Hashtags | F8: Hashtags Used 1 | G8: Average of Engagement_Rate | H8: Average of Clicks
C9: FashionDeals | D9: 50 | F9: FashionDeals | G9: 0.13041434 | H9: 159.76
C10: MyntraFashion | D10: 55 | F10: MyntraFashion | G10: 0.13871112 | H10: 141.34545
C11: MyntraSale | D11: 69 | F11: MyntraSale | G11: 0.15121443 | H11: 145.92754
C12: MyntraTrend | D12: 60 | F12: MyntraTrend | G12: 0.14221518 | H12: 170.23333
C13: StyleWithMyntra | D13: 66 | F13: StyleWithMyntra | G13: 0.1722467 | H13: 141.22727
C16: Content Peformance
C17: Content Type | D17: Average of Likes | E17: Average of Engagement_Rate
C18: Carousel | D18: 2745.7458 | E18: 0.1481492
C19: Image | D19: 2753.4603 | E19: 0.13687494 | H19: video link
C20: Video | D20: 2688.2558 | E20: 0.14814844
C26: Content Type Priorities Per Platform
C27: Average of Engagement_Rate | D27: Content Type
C28: Platform | D28: Carousel | E28: Image | F28: Reel | G28: Story | H28: Text | I28: Video | J28: Grand Total
C29: Facebook | D29: 0.1182059 | E29: 0.11892683 | F29: 0.10810248 | G29: 0.15898978 | H29: 0.10743951 | I29: 0.12899654 | J29: 0.1219729
C30: Instagram | D30: 0.1443986 | E30: 0.14929862 | F30: 0.26004033 | G30: 0.24558274 | H30: 0.12920449 | I30: 0.20623961 | J30: 0.19329258
C31: Twitter | D31: 0.15972488 | E31: 0.14756648 | F31: 0.12428082 | G31: 0.18859717 | H31: 0.12088973 | I31: 0.11980877 | J31: 0.14368407
C32: YouTube | D32: 0.17416554 | E32: 0.15035568 | F32: 0.11688584 | G32: 0.09496533 | H32: 0.11459218 | I32: 0.12968338 | J32: 0.13118494
C33: Grand Total | D33: 0.1481492 | E33: 0.13687494 | F33: 0.15615682 | G33: 0.18425775 | H33: 0.11750674 | I33: 0.14814844 | J33: 0.14828272

Sheet 5.Campaign Effectiveness
A1: Task- 5
G7: Engagement uplift during vs. before campaigns
B8: Campaign_Name | C8: Average of Impressions | D8: Average of Likes | E8: Average of Clicks | G8: Campaign_Name | H8: Average of Engagement_Rate | I8: Sum of Clicks | J8: Sum of Impressions | K8: Sum of Likes
B9: EndOfSeasonSale | C9: 34774.602 | D9: 2804.6386 | E9: 149.10843 | G9: EndOfSeasonSale | H9: 0.15353197 | I9: 12376 | J9: 2886292 | K9: 232785
B10: FashionUpgrade | C10: 38727.319 | D10: 2950.4306 | E10: 155.43056 | G10: Before | H10: 0.15612326 | I10: 11503 | J10: 2686580 | K10: 216535
B11: MyntraFestiveEdit | C11: 33482.718 | D11: 2547 | E11: 159.79487 | G11: During | H11: 0.12027718 | I11: 873 | J11: 199712 | K11: 16250
B12: StyleRevolution | C12: 31460.328 | D12: 2628.4925 | E12: 139.32836 | G12: FashionUpgrade | H12: 0.13707959 | I12: 11191 | J12: 2788367 | K12: 212431
B13: Grand Total | C13: 34647.177 | D13: 2733.3033 | E13: 151.22 | G13: Before | H13: 0.13814561 | I13: 9880 | J13: 2508661 | K13: 188063
G14: During | H14: 0.12855151 | I14: 1311 | J14: 279706 | K14: 24368
G15: MyntraFestiveEdit | H15: 0.14444571 | I15: 12464 | J15: 2611652 | K15: 198666
G16: Before | H16: 0.14493517 | I16: 10805 | J16: 2416564 | K16: 178693
G17: During | H17: 0.14016299 | I17: 1659 | J17: 195088 | K17: 19973
G18: StyleRevolution | H18: 0.15828608 | I18: 9335 | J18: 2107842 | K18: 176109
G19: Before | H19: 0.15086527 | I19: 8386 | J19: 1980477 | K19: 162409
G20: During | H20: 0.22189303 | I20: 949 | J20: 127365 | K20: 13700
G21: Grand Total | H21: 0.14828272 | I21: 45366 | J21: 10394153 | K21: 819991
M23: video link
E33: Average of Engagement_Rate | F33: Column Labels | I33: Engagement Uplift
E34: Campagin_Name | F34: Before | G34: During | H34: Grand Total
E35: EndOfSeasonSale | F35: 0.15612326 | G35: 0.12027718 | H35: 0.15353197 | I35: =(G35-F35)/F35 -> -0.22960116
E36: FashionUpgrade | F36: 0.13814561 | G36: 0.12855151 | H36: 0.13707959 | I36: =(G36-F36)/F36 -> -0.069449185
E37: MyntraFestiveEdit | F37: 0.14493517 | G37: 0.14016299 | H37: 0.14444571 | I37: =(G37-F37)/F37 -> -0.032926292
E38: StyleRevolution | F38: 0.15086527 | G38: 0.22189303 | H38: 0.15828608 | I38: =(G38-F38)/F38 -> 0.47080265 | J38: Highest ROI
E39: Grand Total | F39: 0.14782357 | G39: 0.15257346 | H39: 0.14828272

Sheet 6.Follower Retention & Loy
A1: Task- 6
A6: Weekly growth per platform
A7: Sum of Follower_Growth | B7: Platform
A8: Weeks | B8: Facebook | C8: Instagram | D8: Twitter | E8: YouTube | F8: Grand Total
A9: 45656 | B9: 1776 | C9: 1765 | D9: 1529 | E9: 1460 | F9: 6530
A10: 45698 | B10: 912 | C10: 1723 | D10: 1202 | E10: 1444 | F10: 5281
A11: 45642 | B11: 1377 | C11: 1432 | D11: 1359 | E11: 876 | F11: 5044
A12: 45712 | B12: 1707 | C12: 1375 | D12: 708 | E12: 1016 | F12: 4806
A13: 45628 | B13: 1706 | C13: 1625 | D13: 1173 | E13: 291 | F13: 4795
A14: 45635 | B14: 1373 | C14: 1119 | D14: 1727 | E14: 573 | F14: 4792
A15: 45782 | B15: 339 | C15: 1881 | D15: 1510 | E15: 864 | F15: 4594
A16: 45600 | B16: 540 | C16: 1397 | D16: 1603 | E16: 1044 | F16: 4584
A17: 45544 | B17: 1428 | C17: 1572 | D17: 260 | E17: 1100 | F17: 4360
A18: 45747 | B18: 514 | C18: 641 | D18: 1676 | E18: 1467 | F18: 4298
A19: 45733 | B19: 1116 | C19: 680 | D19: 861 | E19: 1385 | F19: 4042
A20: 45768 | B20: 1045 | C20: 603 | D20: 759 | E20: 1633 | F20: 4040
... A24: 45572 | B24: 1662 | C24: 1872 | D24: 107 | E24: 118 | F24: 3759
A25: 45516 | B25: 1334 | C25: 1325 | D25: 37 | E25: 1032 | F25: 3728 | H25: Platform | I25: Average of Ad_Spend | J25: Average of Follower_Growth
A26: 45726 | B26: 908 | C26: 212 | D26: 1350 | E26: 1242 | F26: 3712 | H26: Facebook | I26: 27590.78 | J26: 711.14
A27: 45705 | B27: 1590 | C27: 965 | D27: -37 | E27: 1175 | F27: 3693 | H27: Instagram | I27: 23287.46 | J27: 960.08
A28: 45677 | B28: 427 | C28: 1572 | D28: 891 | E28: 724 | F28: 3614 | H28: Twitter | I28: 21207.14 | J28: 823.54
A29: 45775 | B29: 453 | C29: 1539 | D29: 948 | E29: 637 | F29: 3577 | H29: YouTube | I29: 24572.94 | J29: 707.34
A30: 45663 | B30: 620 | C30: 903 | D30: 1188 | E30: 846 | F30: 3557 | H30: Grand Total | I30: 24164.58 | J30: 800.525
A31: 45446 | B31: 1002 | C31: 1047 | D31: 415 | E31: 1090 | F31: 3554
A32: 45684 | B32: 898 | C32: -166 | D32: 1426 | E32: 1225 | F32: 3383
A33: 45558 | B33: -19 | C33: 666 | D33: 1680 | E33: 1006 | F33: 3333
A34: 45565 | B34: -179 | C34: 1025 | D34: 599 | E34: 1706 | F34: 3151
A35: 45481 | B35: 309 | C35: 1672 | D35: 547 | E35: 514 | F35: 3042
A36: 45467 | B36: 1670 | C36: 629 | D36: 835 | E36: -123 | F36: 3011 | L36: video link
A37: 45523 | B37: 1058 | C37: 76 | D37: 1665 | E37: 190 | F37: 2989
A38: 45453 | B38: 1283 | C38: 517 | D38: 186 | E38: 994 | F38: 2980
A39: 45530 | B39: 37 | C39: 1609 | D39: 1229 | E39: 28 | F39: 2903
A40: 45537 | B40: 1045 | C40: 1247 | D40: 197 | E40: 333 | F40: 2822
A41: 45586 | B41: 439 | C41: 262 | D41: 636 | E41: 1484 | F41: 2821
A42: 45670 | B42: 298 | C42: 1722 | D42: -144 | E42: 901 | F42: 2777
A43: 45495 | B43: 961 | C43: 159 | D43: 1316 | E43: 317 | F43: 2753
A44: 45593 | B44: 386 | C44: 576 | D44: 37 | E44: 1657 | F44: 2656
A45: 45754 | B45: 1029 | C45: 167 | D45: 1007 | E45: 209 | F45: 2412
A46: 45719 | B46: -119 | C46: 1315 | D46: 899 | E46: 315 | F46: 2410
A47: 45607 | B47: -106 | C47: 902 | D47: 1150 | E47: 349 | F47: 2295
...
